[2025-07-31T19:33:51.470+0000] {taskinstance.py:1157} INFO - Dependencies all met for dep_context=non-requeueable deps ti=<TaskInstance: postgres_pipeline_example.insert_row manual__2025-07-31T19:33:47.869280+00:00 [queued]>
[2025-07-31T19:33:51.481+0000] {taskinstance.py:1157} INFO - Dependencies all met for dep_context=requeueable deps ti=<TaskInstance: postgres_pipeline_example.insert_row manual__2025-07-31T19:33:47.869280+00:00 [queued]>
[2025-07-31T19:33:51.481+0000] {taskinstance.py:1359} INFO - Starting attempt 1 of 1
[2025-07-31T19:33:51.494+0000] {taskinstance.py:1380} INFO - Executing <Task(PostgresOperator): insert_row> on 2025-07-31 19:33:47.869280+00:00
[2025-07-31T19:33:51.498+0000] {standard_task_runner.py:57} INFO - Started process 877 to run task
[2025-07-31T19:33:51.501+0000] {standard_task_runner.py:84} INFO - Running: ['***', 'tasks', 'run', 'postgres_pipeline_example', 'insert_row', 'manual__2025-07-31T19:33:47.869280+00:00', '--job-id', '251', '--raw', '--subdir', 'DAGS_FOLDER/jobs_dag.py', '--cfg-path', '/tmp/tmp7eqidduv']
[2025-07-31T19:33:51.505+0000] {standard_task_runner.py:85} INFO - Job 251: Subtask insert_row
[2025-07-31T19:33:51.553+0000] {task_command.py:415} INFO - Running <TaskInstance: postgres_pipeline_example.insert_row manual__2025-07-31T19:33:47.869280+00:00 [running]> on host 39aa5c3cd22d
[2025-07-31T19:33:51.605+0000] {abstractoperator.py:709} ERROR - Exception rendering Jinja template for task 'insert_row', field 'sql'. Template: '\n            INSERT INTO {{ params.table_name }} (custom_id, user_name, timestamp)\n            VALUES (%(custom_id)s, %(user_name)s, %(timestamp)s);\n        '
Traceback (most recent call last):
  File "/home/airflow/.local/lib/python3.8/site-packages/airflow/models/abstractoperator.py", line 701, in _do_render_template_fields
    rendered_content = self.render_template(
  File "/home/airflow/.local/lib/python3.8/site-packages/airflow/template/templater.py", line 157, in render_template
    return self._render(template, context)
  File "/home/airflow/.local/lib/python3.8/site-packages/airflow/models/abstractoperator.py", line 655, in _render
    return super()._render(template, context, dag=dag)
  File "/home/airflow/.local/lib/python3.8/site-packages/airflow/template/templater.py", line 114, in _render
    return render_template_to_string(template, context)
  File "/home/airflow/.local/lib/python3.8/site-packages/airflow/utils/helpers.py", line 289, in render_template_to_string
    return render_template(template, cast(MutableMapping[str, Any], context), native=False)
  File "/home/airflow/.local/lib/python3.8/site-packages/airflow/utils/helpers.py", line 284, in render_template
    return "".join(nodes)
  File "<template>", line 13, in root
  File "/home/airflow/.local/lib/python3.8/site-packages/jinja2/runtime.py", line 852, in _fail_with_undefined_error
    raise self._undefined_exception(self._undefined_message)
jinja2.exceptions.UndefinedError: 'dict object' has no attribute 'table_name'
[2025-07-31T19:33:51.607+0000] {taskinstance.py:1935} ERROR - Task failed with exception
Traceback (most recent call last):
  File "/home/airflow/.local/lib/python3.8/site-packages/airflow/models/taskinstance.py", line 1516, in _run_raw_task
    self._execute_task_with_callbacks(context, test_mode, session=session)
  File "/home/airflow/.local/lib/python3.8/site-packages/airflow/models/taskinstance.py", line 1645, in _execute_task_with_callbacks
    task_orig = self.render_templates(context=context)
  File "/home/airflow/.local/lib/python3.8/site-packages/airflow/models/taskinstance.py", line 2283, in render_templates
    original_task.render_template_fields(context)
  File "/home/airflow/.local/lib/python3.8/site-packages/airflow/models/baseoperator.py", line 1245, in render_template_fields
    self._do_render_template_fields(self, self.template_fields, context, jinja_env, set())
  File "/home/airflow/.local/lib/python3.8/site-packages/airflow/utils/session.py", line 77, in wrapper
    return func(*args, session=session, **kwargs)
  File "/home/airflow/.local/lib/python3.8/site-packages/airflow/models/abstractoperator.py", line 701, in _do_render_template_fields
    rendered_content = self.render_template(
  File "/home/airflow/.local/lib/python3.8/site-packages/airflow/template/templater.py", line 157, in render_template
    return self._render(template, context)
  File "/home/airflow/.local/lib/python3.8/site-packages/airflow/models/abstractoperator.py", line 655, in _render
    return super()._render(template, context, dag=dag)
  File "/home/airflow/.local/lib/python3.8/site-packages/airflow/template/templater.py", line 114, in _render
    return render_template_to_string(template, context)
  File "/home/airflow/.local/lib/python3.8/site-packages/airflow/utils/helpers.py", line 289, in render_template_to_string
    return render_template(template, cast(MutableMapping[str, Any], context), native=False)
  File "/home/airflow/.local/lib/python3.8/site-packages/airflow/utils/helpers.py", line 284, in render_template
    return "".join(nodes)
  File "<template>", line 13, in root
  File "/home/airflow/.local/lib/python3.8/site-packages/jinja2/runtime.py", line 852, in _fail_with_undefined_error
    raise self._undefined_exception(self._undefined_message)
jinja2.exceptions.UndefinedError: 'dict object' has no attribute 'table_name'
[2025-07-31T19:33:51.616+0000] {taskinstance.py:1398} INFO - Marking task as FAILED. dag_id=postgres_pipeline_example, task_id=insert_row, execution_date=20250731T193347, start_date=20250731T193351, end_date=20250731T193351
[2025-07-31T19:33:51.630+0000] {standard_task_runner.py:104} ERROR - Failed to execute job 251 for task insert_row ('dict object' has no attribute 'table_name'; 877)
[2025-07-31T19:33:51.643+0000] {local_task_job_runner.py:228} INFO - Task exited with return code 1
[2025-07-31T19:33:51.667+0000] {taskinstance.py:2776} INFO - 0 downstream tasks scheduled from follow-on schedule check
